<?xml version="1.0" ?>
<robot name = "camel_hard_IceCream">

  <material name="red">
    <color rgba="0.914 0.263 0.212 0.7"/>
  </material>

  <material name="stylish">
    <color rgba="0.243 0.271 0.318 0.9"/>
  </material>

  <material name="lime">
    <color rgba="0.804 0.863 0.223 0.9"/>
  </material>

  <material name="blue">
    <color rgba="0.329 0.463 0.890 0.7 "/>
  </material>

  <link name="world"/>
  <joint name="fixed_world" type="fixed">
    <parent link="world"/>
    <child link="base"/>
  </joint>

  <link name="base">
    <visual>
      <origin rpy="1.570796 0 0 " xyz="0 0 0.01275"/>
      <geometry>
        <cylinder length="0.02" radius="0.005"/>
      </geometry>
      <material name="stylish"/>
    </visual>
    <inertial>
      <origin rpy="0 0 0 " xyz="0 0 0.01275"/>
      <mass value="0.01"/>
      <inertia ixx="0.001229" ixy="0.0" ixz="0.0" iyy="0.001234" iyz="0.0" izz="0.000013"/>
    </inertial>
  </link>

  <joint name="base-pitch" type="revolute">
    <origin rpy="0 0 0" xyz="0 0 0.01275"/>
    <parent link="base"/>
    <child link="rod"/>
    <axis xyz="0 1 0"/>
  </joint>

  <link name="rod">
    <visual>
      <origin rpy="0.0 0.0 0.0" xyz="0.0 0.0 0.199186"/>
      <geometry>
        <box size="0.03 0.02 0.398372"/>
      </geometry>
      <material name="blue"/>
    </visual>

    <inertial>
      <origin rpy="0.0 0.0 0.0" xyz="0.0 0.0 0.199186"/>
      <mass value="2.179"/>
      <inertia ixx="0.02889" ixy="0.0" ixz="0.0" iyy="0.0289807" iyz="0.0" izz="0.000236058"/>
    </inertial>

    <collision>
      <origin rpy="0.0 0.0 0.0" xyz="0.0 0.0 0.199186"/>
      <geometry>
        <box size="0.003 0.002 0.398372"/>
      </geometry>
    </collision>
  </link>

  <joint name="hip-pitch" type="revolute">
    <origin rpy="0.0 0.0 0.0" xyz="0.0 0.0 0.398372"/>
    <parent link="rod"/>
    <child link="body"/>
    <axis xyz = "0 1 0"/>
  </joint>

  <link name="body">
    <visual>
      <origin rpy="0.0 0.0 0.0" xyz="0.241 0.0 0.0"/>
      <geometry>
        <box size="0.482 0.122265 0.111"/>
      </geometry>
      <material name="red"/>
    </visual>

    <inertial>
      <origin rpy="0.0 0.0 0.0" xyz="0.241 0.0 0.0"/>
      <mass value="3.5215"/>
      <inertia ixx="0.00800253" ixy="0.0" ixz="0.0" iyy="0.0717931" iyz="0.0" izz="0.0725642"/>
    </inertial>

    <collision>
      <origin rpy="0.0 0.0 0.0" xyz="0.241 0.0 0.0"/>
      <geometry>
        <box size="0.482 0.122265 0.111"/>
      </geometry>
    </collision>

  </link>
</robot>