<?xml version="1.0" ?>
<robot name="obstacle">

  <material name="black">
    <color rgba="0.0 0.0 0.0 1.0"/>
  </material>

  <material name="gray">
    <color rgba="0.5 0.5 0.5 1.0"/>
  </material>

  <material name="Aquamarine">
    <color rgba="0.364 0.733 0.608 1.0"/>
  </material>

  <material name="Aqua">
    <color rgba="0.0 0.733 0.733 1.0"/>
  </material>

  <link name="world"/>
  <joint name="base" type="fixed">
    <origin rpy="0 0 0" xyz="-0.5 -0.05 0"/>
    <parent link="world"/>
    <child link="goalpostL"/>
  </joint>

  <link name="goalpostL">
    <visual>
      <origin rpy="0 0 0" xyz="0.5 0 0.0625"/>
      <geometry>
        <box size="0.025 0.025 0.125"/>
      </geometry>
      <material name="Aqua"/>
    </visual>

    <collision>
      <origin rpy="0 0 0" xyz="0.5 0 0.0625"/>
      <geometry>
        <box size="0.025 0.025 0.125"/>
      </geometry>
    </collision>

    <inertial>
      <mass value="100.0"/>
      <inertia ixx="1.0" ixy="0.0" ixz="0.0" iyy="1.0" iyz="0.0" izz="1.0"/>
    </inertial>
  </link>

  <joint name="cornerL" type="fixed">
    <origin rpy="0 0 0" xyz="0.5 0 0.125"/>
    <parent link="goalpostL"/>
    <child link="crossbar"/>
  </joint>

  <link name="crossbar">
    <visual>
      <origin rpy="0 0 0" xyz="0 -0.1125 0.0125"/>
      <geometry>
        <box size="0.025 0.25 0.025"/>
      </geometry>
      <material name="Aqua"/>
    </visual>

    <collision>
      <origin rpy="0 0 0" xyz="0 -0.1125 0.0125"/>
      <geometry>
        <box size="0.025 0.25 0.025"/>
      </geometry>
    </collision>

    <inertial>
      <mass value="100.0"/>
      <inertia ixx="1.0" ixy="0.0" ixz="0.0" iyy="1.0" iyz="0.0" izz="1.0"/>
    </inertial>
  </link>

  <joint name="cornerR" type="revolute">
    <origin rpy="0 0 0" xyz="0 -0.25 0"/>
    <parent link="crossbar"/>
    <child link="goalpostR"/>
    <axis xyz="0 0 1"/>
  </joint>

  <link name="goalpostR">
    <visual>
      <origin rpy="0 0 0" xyz="0 0.025 -0.0625"/>
      <geometry>
        <box size="0.025 0.025 0.125"/>
      </geometry>
      <material name="Aqua"/>
    </visual>

    <collision>
      <origin rpy="0 0 0" xyz="0 0.025 -0.0625"/>
      <geometry>
        <box size="0.025 0.025 0.125"/>
      </geometry>
    </collision>

    <inertial>
      <mass value="100.0"/>
      <inertia ixx="1.0" ixy="0.0" ixz="0.0" iyy="1.0" iyz="0.0" izz="1.0"/>
    </inertial>
  </link>
</robot>