<?xml version="1.0" ?>
<robot name="camel_dong_dog">

  <material name="black">
    <color rgba="0.0 0.0 0.0 0.9"/>
  </material>

  <material name="black1">
    <color rgba="0.0 0.0 0.0 1"/>
  </material>

  <material name="gray1">
    <color rgba="0.75 0.75 0.75 1"/>
  </material>

  <material name="gray2">
    <color rgba="0.5 0.5 0.5 0.9"/>
  </material>

  <material name="gray3">
    <color rgba="0.25 0.25 0.25 0.9"/>
  </material>

  <link name="world"/>

  <joint name="fixed_world" type="fixed">
    <parent link="world"/>
    <child link="base"/>
  </joint>

  <link name="base">
    <visual>
      <origin rpy="0 0 0" xyz="0 0 0"/>
      <geometry>
        <box size="0.25 0.25 1"/>
      </geometry>
      <material name="black"/>
    </visual>

    <inertial>
      <mass value="10"/>
      <inertia ixx="1.0" ixy="0.0" ixz="0.0" iyy="1.0" iyz="0.0" izz="1.0"/>
    </inertial>
  </link>

  <joint name="base" type="prismatic">
    <origin rpy="0 0 0" xyz="0 -0.025 0.0"/>
    <parent link="base"/>
    <child link="shoulder"/>
    <axis xyz="0 0 1"/>
  </joint>

  <link name="shoulder">
    <visual>
      <origin rpy="0 0 0" xyz="0 0 0"/>
      <geometry>
        <mesh filename="shoulder.stl"/>
      </geometry>
      <material name="gray1"/>
    </visual>
    <inertial>
      <mass value="3.0"/>
      <inertia ixx="1" ixy="0.0" ixz="0.0" iyy="1" iyz="0.0" izz="1"/>
    </inertial>
  </link>

  <link name="thigh">
    <visual>
      <origin rpy="0 0 0" xyz="0.55 -0.125 0"/>
      <geometry>
        <mesh filename="thigh.stl"/>
      </geometry>
      <material name="black"/>
    </visual>
    <inertial>
      <mass value="3.0"/>
      <inertia ixx="1" ixy="0.0" ixz="0.0" iyy="1" iyz="0.0" izz="1"/>
    </inertial>
  </link>

  <link name="calf">
    <visual>
      <origin rpy="0 0 0" xyz="0.425 -0.25 -0.3"/>
      <geometry>
        <mesh filename="calf.stl"/>
      </geometry>
      <material name="gray1"/>
    </visual>
    <inertial>
      <mass value="3.0"/>
      <inertia ixx="1" ixy="0.0" ixz="0.0" iyy="1" iyz="0.0" izz="1"/>
    </inertial>
  </link>

  <joint name="J1" type="revolute">
    <origin rpy="0 0 0" xyz="0 0 0"/>
    <parent link="shoulder"/>
    <child link="thigh"/>
    <axis xyz="1 0 0"/>
  </joint>

  <joint name="J2" type="revolute">
    <origin rpy="0 0 0" xyz="0 0 0"/>
    <parent link="thigh"/>
    <child link="calf"/>
    <axis xyz="1 0 0"/>
  </joint>
</robot>