<?xml version="1.0" ?>
<robot name = "six_dof_arm">
    <meterial name="black">
        <color rgba="1.0 0.0 1.0 0.5"/>
    </meterial>

    <link name ="world"/>

    <joint name = "fixed_world" type = "fixed">
        <origin rpy="0 0 0" xyz="0 0 0"/>
        <parent link="world"/>
        <child link = "1"/>
    </joint>

    <link name="1">
        <visual>
            <origin rpy="0 0 0" xyz = "0 0 0"/>
            <geometry>
                <mesh filename = "1.stl" scale ="0.001 0.001 0.001"/>
            </geometry>
            <material name = "black"/>
        </visual>
        <inertia>
            <mass value = "3.0"/>
            <inertia ixx="1" ixy="0" ixz="0" iyy="1" iyz="0" izz="1"/>
        </inertia>
    </link>

    <joint name="joint1" type="revolute">
        <origin rpy="0 0 0" xyz="0.055 0.03 0.05"/>
        <parent link="1"/>
        <child link="2"/>
        <axis xyz="0 0 1"/>
    </joint>

    <link name="2">
        <visual>
            <origin rpy="0 0 -1.5708" xyz = "-0.02 0.153 -0.015"/>
            <geometry>
                <mesh filename = "2.stl" scale ="0.001 0.001 0.001"/>
            </geometry>
            <material name = "black"/>
        </visual>
        <inertia>
            <mass value = "3.0"/>
            <inertia ixx="1" ixy="0" ixz="0" iyy="1" iyz="0" izz="1"/>
        </inertia>
    </link>

    <joint name="joint2" type="revolute">
        <origin rpy="0 0 0" xyz="-0.0008 -0.023 0.04"/>
        <parent link="2"/>
        <child link="3"/>
        <axis xyz="0 1 0"/>
    </joint>

    <link name="3">
        <visual>
            <origin rpy="0 0 -1.5708" xyz = "-0.0222 0.276 -0.0551"/>
            <geometry>
                <mesh filename = "3.stl" scale ="0.001 0.001 0.001"/>
            </geometry>
            <material name = "black"/>
        </visual>
        <inertia>
            <mass value = "3.0"/>
            <inertia ixx="1" ixy="0" ixz="0" iyy="1" iyz="0" izz="1"/>
        </inertia>
    </link>

    <joint name="joint3" type="revolute">
        <origin rpy="0 0 0" xyz="0 0.022 0.172"/>
        <parent link="3"/>
        <child link="4"/>
        <axis xyz="0 0 1"/>
    </joint>

    <link name="4">
        <visual>
            <origin rpy="0 0 -1.5708" xyz = "-0.018 0.354 -0.227"/>
            <geometry>
                <mesh filename = "4.stl" scale ="0.001 0.001 0.001"/>
            </geometry>
            <material name = "black"/>
        </visual>
        <inertia>
            <mass value = "3.0"/>
            <inertia ixx="1" ixy="0" ixz="0" iyy="1" iyz="0" izz="1"/>
        </inertia>
    </link>

    <joint name="joint4" type="revolute">
        <origin rpy="0 0 0" xyz="0 -0.022 0.042"/>
        <parent link="4"/>
        <child link="5"/>
        <axis xyz="0 1 0"/>
    </joint>

    <link name="5">
        <visual>
            <origin rpy="0 0 -1.5708" xyz = "-0.018 0.476 -0.2695"/>
            <geometry>
                <mesh filename = "5.stl" scale ="0.001 0.001 0.001"/>
            </geometry>
            <material name = "black"/>
        </visual>
        <inertia>
            <mass value = "3.0"/>
            <inertia ixx="1" ixy="0" ixz="0" iyy="1" iyz="0" izz="1"/>
        </inertia>
    </link>

    <joint name="joint5" type="revolute">
        <origin rpy="0 0 0" xyz="0 0 0.14"/>
        <parent link="5"/>
        <child link="6"/>
        <axis xyz="0 1 0"/>
    </joint>

    <link name="6">
        <visual>
            <origin rpy="0 0 -1.5708" xyz = "-0.022 0.5759 -0.4095"/>
            <geometry>
                <mesh filename = "6.stl" scale ="0.001 0.001 0.001"/>
            </geometry>
            <material name = "black"/>
        </visual>
        <inertia>
            <mass value = "3.0"/>
            <inertia ixx="1" ixy="0" ixz="0" iyy="1" iyz="0" izz="1"/>
        </inertia>
    </link>

    <joint name="joint6" type="revolute">
        <origin rpy="0 0 0" xyz="0 0.02 0.095"/>
        <parent link="6"/>
        <child link="7"/>
        <axis xyz="0 0 1"/>
    </joint>

    <link name="7">
        <visual>
            <origin rpy="0 0 -1.5708" xyz = "-0.0064 0.656 -0.5045"/>
            <geometry>
                <mesh filename = "7.stl" scale ="0.001 0.001 0.001"/>
            </geometry>
            <material name = "black"/>
        </visual>
        <inertia>
            <mass value = "3.0"/>
            <inertia ixx="1" ixy="0" ixz="0" iyy="1" iyz="0" izz="1"/>
        </inertia>
    </link>

</robot>